---
title: try...catch
order: 3
---

## 功能

try...catch 可以测试代码中的错误。try 部分包含需要运行的代码，而 catch 部分包含错误发生时运行的代码。

## 语法

```js
try {
  //在此运行代码
} catch (err) {
  //在此处理错误
}
```

举个栗子：

```js
try {
  throw new Error('111');
} catch (e) {
  console.log(e); // Error: 111
}
```

> try...catch 无法捕捉异步的错误，当然在 `async/await` 中可以，这也是 `async/await` 的特殊之处。
